# -*- coding: utf-8 -*-
<!--Modified Version of Example.xml from MuJoCo Docs-->

<mujoco model="example">
  <compiler coordinate="global"/>

  <option> 
  <flag sensornoise="enable" />
  </option>

  <default>
    <geom rgba=".8 .6 .4 1"/>
  </default>

  <asset>
    <texture type="skybox" builtin="gradient" rgb1="1 1 1" rgb2=".6 .8 1" width="256" height="256"/>
  </asset>

  <worldbody>
    <light pos="0 1 1" dir="0 -1 -1" diffuse="1 1 1"/>
    <body>
      <geom type="capsule" fromto="0 0 1  0 0 0.6" size="0.06"/>
      <joint type="ball" pos="0 0 1"/>
      <body>
        <geom type="capsule" fromto="0 0 0.6  0.3 0 0.6" size="0.04"/>
        <joint name="joint1" type="hinge" pos="0 0 0.6" axis="0 1 0"/>
        <joint type="hinge" pos="0 0 0.6" axis="1 0 0"/>
        <body>
          <geom type="ellipsoid" pos="0.4 0 0.6" size="0.1 0.08 0.02"/>
          <site name="end1" pos="0.5 0 0.6" type="sphere" size="0.01"/>
          <joint name="joint2" type="hinge" pos="0.3 0 0.6" axis="0 1 0"/>
          <joint type="hinge" pos="0.3 0 0.6" axis="0 0 1"/>
        </body>
      </body>
    </body>
    <body>
      <geom type="cylinder" fromto="0.5 0 0.2  0.5 0 0" size="0.07"/>
      <site name="end2" pos="0.5 0 0.2" type="sphere" size="0.01"/>
      <joint type="free"/>
    </body>
  </worldbody>

  <tendon>
    <spatial limited="true" range="0 0.6" width="0.005">
      <site site="end1"/>
      <site site="end2"/>
    </spatial>
  </tendon>
  
  <actuator>
      <position name="servo_pos1" site='end1' kp='20'/>
      <velocity name="servo_vel1" site='end1' />
      <motor name="motor1" site='end1' gear='1' />
      <position name="servo_pos2" site='end2' kp='20' />
      <velocity name="servo_vel2" site='end2' />
      <motor name='motor2' site='end2' gear='1' />
  </actuator>
  
  <sensor>
      <jointpos name='sensor_pos1' joint='joint1' />
      <jointpos name='sensor_vel1' joint='joint1' />
      <jointvel name='sensor_pos2' joint='joint2' />
      <jointvel name='sensor_vel2' joint='joint2' />
  </sensor>
  
</mujoco>